/usr/lib/python3/dist-packages/requests/__init__.py:89: RequestsDependencyWarning: urllib3 (2.0.4) or chardet (3.0.4) doesn't match a supported version!
  warnings.warn("urllib3 ({}) or chardet ({}) doesn't match a supported "
wandb: Currently logged in as: daidv. Use `wandb login --relogin` to force relogin
wandb: Tracking run with wandb version 0.15.9
wandb: Run data is saved locally in /home/s223540177/dai/SimpleRL/A2C/wandb/run-20230903_120752-38ropzp4
wandb: Run `wandb offline` to turn off syncing.
wandb: Syncing run rosy-glade-14
wandb: ‚≠êÔ∏è View project at https://wandb.ai/daidv/A2C_CartPole-v1
wandb: üöÄ View run at https://wandb.ai/daidv/A2C_CartPole-v1/runs/38ropzp4
/usr/lib/python3/dist-packages/requests/__init__.py:89: RequestsDependencyWarning: urllib3 (2.0.4) or chardet (3.0.4) doesn't match a supported version!
  warnings.warn("urllib3 ({}) or chardet ({}) doesn't match a supported "
Thread SenderThread:
Traceback (most recent call last):
  File "/home/s223540177/.local/lib/python3.8/site-packages/wandb/sdk/internal/internal_util.py", line 49, in run
    self._run()
  File "/home/s223540177/.local/lib/python3.8/site-packages/wandb/sdk/internal/internal_util.py", line 100, in _run
    self._process(record)
  File "/home/s223540177/.local/lib/python3.8/site-packages/wandb/sdk/internal/internal.py", line 328, in _process
    self._sm.send(record)
  File "/home/s223540177/.local/lib/python3.8/site-packages/wandb/sdk/internal/sender.py", line 386, in send
    send_handler(record)
  File "/home/s223540177/.local/lib/python3.8/site-packages/wandb/sdk/internal/sender.py", line 408, in send_request
    send_handler(record)
  File "/home/s223540177/.local/lib/python3.8/site-packages/wandb/sdk/internal/sender.py", line 1145, in send_request_summary_record
    self._update_summary_record(record.request.summary_record.summary)
  File "/home/s223540177/.local/lib/python3.8/site-packages/wandb/sdk/internal/sender.py", line 1139, in _update_summary_record
    self._update_summary()
  File "/home/s223540177/.local/lib/python3.8/site-packages/wandb/sdk/internal/sender.py", line 1157, in _update_summary
    with open(summary_path, "w") as f:
FileNotFoundError: [Errno 2] No such file or directory: '/home/s223540177/dai/SimpleRL/A2C/wandb/run-20230903_120752-38ropzp4/files/wandb-summary.json'
wandb: ERROR Internal wandb error: file data was not synced
Traceback (most recent call last):
  File "main.py", line 215, in <module>
    main(args.n_epochs, args.max_ts, args.n_trials, args.test_epochs)
  File "main.py", line 160, in main
    wandb.log({'Episode Length': ts, 'Running Reward': running_reward, 'Trial': trial, 'Epoch': epoch})
  File "/home/s223540177/.local/lib/python3.8/site-packages/wandb/sdk/wandb_run.py", line 390, in wrapper
    return func(self, *args, **kwargs)
  File "/home/s223540177/.local/lib/python3.8/site-packages/wandb/sdk/wandb_run.py", line 341, in wrapper_fn
    return func(self, *args, **kwargs)
  File "/home/s223540177/.local/lib/python3.8/site-packages/wandb/sdk/wandb_run.py", line 331, in wrapper
    return func(self, *args, **kwargs)
  File "/home/s223540177/.local/lib/python3.8/site-packages/wandb/sdk/wandb_run.py", line 1752, in log
    self._log(data=data, step=step, commit=commit)
  File "/home/s223540177/.local/lib/python3.8/site-packages/wandb/sdk/wandb_run.py", line 1527, in _log
    self._partial_history_callback(data, step, commit)
  File "/home/s223540177/.local/lib/python3.8/site-packages/wandb/sdk/wandb_run.py", line 1397, in _partial_history_callback
    self._backend.interface.publish_partial_history(
  File "/home/s223540177/.local/lib/python3.8/site-packages/wandb/sdk/interface/interface.py", line 653, in publish_partial_history
    self._publish_partial_history(partial_history)
  File "/home/s223540177/.local/lib/python3.8/site-packages/wandb/sdk/interface/interface_shared.py", line 89, in _publish_partial_history
    self._publish(rec)
  File "/home/s223540177/.local/lib/python3.8/site-packages/wandb/sdk/interface/interface_sock.py", line 51, in _publish
    self._sock_client.send_record_publish(record)
  File "/home/s223540177/.local/lib/python3.8/site-packages/wandb/sdk/lib/sock_client.py", line 221, in send_record_publish
    self.send_server_request(server_req)
  File "/home/s223540177/.local/lib/python3.8/site-packages/wandb/sdk/lib/sock_client.py", line 155, in send_server_request
    self._send_message(msg)
  File "/home/s223540177/.local/lib/python3.8/site-packages/wandb/sdk/lib/sock_client.py", line 152, in _send_message
    self._sendall_with_error_handle(header + data)
  File "/home/s223540177/.local/lib/python3.8/site-packages/wandb/sdk/lib/sock_client.py", line 130, in _sendall_with_error_handle
    sent = self._sock.send(data)
BrokenPipeError: [Errno 32] Broken pipe
Traceback (most recent call last):
  File "main.py", line 215, in <module>
    main(args.n_epochs, args.max_ts, args.n_trials, args.test_epochs)
  File "main.py", line 160, in main
    wandb.log({'Episode Length': ts, 'Running Reward': running_reward, 'Trial': trial, 'Epoch': epoch})
  File "/home/s223540177/.local/lib/python3.8/site-packages/wandb/sdk/wandb_run.py", line 390, in wrapper
    return func(self, *args, **kwargs)
  File "/home/s223540177/.local/lib/python3.8/site-packages/wandb/sdk/wandb_run.py", line 341, in wrapper_fn
    return func(self, *args, **kwargs)
  File "/home/s223540177/.local/lib/python3.8/site-packages/wandb/sdk/wandb_run.py", line 331, in wrapper
    return func(self, *args, **kwargs)
  File "/home/s223540177/.local/lib/python3.8/site-packages/wandb/sdk/wandb_run.py", line 1752, in log
    self._log(data=data, step=step, commit=commit)
  File "/home/s223540177/.local/lib/python3.8/site-packages/wandb/sdk/wandb_run.py", line 1527, in _log
    self._partial_history_callback(data, step, commit)
  File "/home/s223540177/.local/lib/python3.8/site-packages/wandb/sdk/wandb_run.py", line 1397, in _partial_history_callback
    self._backend.interface.publish_partial_history(
  File "/home/s223540177/.local/lib/python3.8/site-packages/wandb/sdk/interface/interface.py", line 653, in publish_partial_history
    self._publish_partial_history(partial_history)
  File "/home/s223540177/.local/lib/python3.8/site-packages/wandb/sdk/interface/interface_shared.py", line 89, in _publish_partial_history
    self._publish(rec)
  File "/home/s223540177/.local/lib/python3.8/site-packages/wandb/sdk/interface/interface_sock.py", line 51, in _publish
    self._sock_client.send_record_publish(record)
  File "/home/s223540177/.local/lib/python3.8/site-packages/wandb/sdk/lib/sock_client.py", line 221, in send_record_publish
    self.send_server_request(server_req)
  File "/home/s223540177/.local/lib/python3.8/site-packages/wandb/sdk/lib/sock_client.py", line 155, in send_server_request
    self._send_message(msg)
  File "/home/s223540177/.local/lib/python3.8/site-packages/wandb/sdk/lib/sock_client.py", line 152, in _send_message
    self._sendall_with_error_handle(header + data)
  File "/home/s223540177/.local/lib/python3.8/site-packages/wandb/sdk/lib/sock_client.py", line 130, in _sendall_with_error_handle
    sent = self._sock.send(data)
BrokenPipeError: [Errno 32] Broken pipe
Error in sys.excepthook:
Traceback (most recent call last):
  File "/usr/lib/python3/dist-packages/apport_python_hook.py", line 76, in apport_excepthook
    binary = os.path.realpath(os.path.join(os.getcwd(), sys.argv[0]))
FileNotFoundError: [Errno 2] No such file or directory

Original exception was:
Traceback (most recent call last):
  File "main.py", line 215, in <module>
    main(args.n_epochs, args.max_ts, args.n_trials, args.test_epochs)
  File "main.py", line 160, in main
    wandb.log({'Episode Length': ts, 'Running Reward': running_reward, 'Trial': trial, 'Epoch': epoch})
  File "/home/s223540177/.local/lib/python3.8/site-packages/wandb/sdk/wandb_run.py", line 390, in wrapper
    return func(self, *args, **kwargs)
  File "/home/s223540177/.local/lib/python3.8/site-packages/wandb/sdk/wandb_run.py", line 341, in wrapper_fn
    return func(self, *args, **kwargs)
  File "/home/s223540177/.local/lib/python3.8/site-packages/wandb/sdk/wandb_run.py", line 331, in wrapper
    return func(self, *args, **kwargs)
  File "/home/s223540177/.local/lib/python3.8/site-packages/wandb/sdk/wandb_run.py", line 1752, in log
    self._log(data=data, step=step, commit=commit)
  File "/home/s223540177/.local/lib/python3.8/site-packages/wandb/sdk/wandb_run.py", line 1527, in _log
    self._partial_history_callback(data, step, commit)
  File "/home/s223540177/.local/lib/python3.8/site-packages/wandb/sdk/wandb_run.py", line 1397, in _partial_history_callback
    self._backend.interface.publish_partial_history(
  File "/home/s223540177/.local/lib/python3.8/site-packages/wandb/sdk/interface/interface.py", line 653, in publish_partial_history
    self._publish_partial_history(partial_history)
  File "/home/s223540177/.local/lib/python3.8/site-packages/wandb/sdk/interface/interface_shared.py", line 89, in _publish_partial_history
    self._publish(rec)
  File "/home/s223540177/.local/lib/python3.8/site-packages/wandb/sdk/interface/interface_sock.py", line 51, in _publish
    self._sock_client.send_record_publish(record)
  File "/home/s223540177/.local/lib/python3.8/site-packages/wandb/sdk/lib/sock_client.py", line 221, in send_record_publish
    self.send_server_request(server_req)
  File "/home/s223540177/.local/lib/python3.8/site-packages/wandb/sdk/lib/sock_client.py", line 155, in send_server_request
    self._send_message(msg)
  File "/home/s223540177/.local/lib/python3.8/site-packages/wandb/sdk/lib/sock_client.py", line 152, in _send_message
    self._sendall_with_error_handle(header + data)
  File "/home/s223540177/.local/lib/python3.8/site-packages/wandb/sdk/lib/sock_client.py", line 130, in _sendall_with_error_handle
    sent = self._sock.send(data)
BrokenPipeError: [Errno 32] Broken pipe
wandb: While tearing down the service manager. The following error has occurred: [Errno 32] Broken pipe
